package blfngl.fallout.world;

import java.util.Random;

import net.minecraft.block.Block;
import net.minecraft.world.World;
import net.minecraft.world.gen.feature.WorldGenerator;

public class StructureGasStation extends WorldGenerator
{
	protected int[] GetValidSpawnBlocks()
	{
		return new int[]{Block.dirt.blockID};
	}

	public boolean LocationIsValidSpawn(World world, int i, int j, int k)
	{
		int distanceToAir = 0;
		int checkID = world.getBlockId(i, j, k);

		while (checkID != 0)
		{
			distanceToAir++;
			checkID = world.getBlockId(i, j + distanceToAir, k);
		}

		if (distanceToAir > 0)
		{
			return false;
		}

		j += distanceToAir - 1;

		int blockID = world.getBlockId(i, j, k);
		int blockIDAbove = world.getBlockId(i, j+1, k);
		int blockIDBelow = world.getBlockId(i, j-1, k);
		for (int x : GetValidSpawnBlocks())
		{
			if (blockIDAbove != 0)
			{
				return false;
			}

			if (blockID == x)
			{
				return true;
			}

			else if (blockID == Block.snow.blockID && blockIDBelow == x)
			{
				return true;
			}
		}
		return false;
	}

	public StructureGasStation()
	{

	}

	public boolean generate(World world, Random rand, int i, int j, int k)
	{
		//check that each corner is one of the valid spawn blocks
		if(!LocationIsValidSpawn(world, i, j, k) || !LocationIsValidSpawn(world, i + 26, j, k) || !LocationIsValidSpawn(world, i + 26, j, k + 20) || !LocationIsValidSpawn(world, i, j, k + 20))
		{
			return false;
		}

		world.setBlock(i + 0, j + 0, k + 4, Block.dirt.blockID);
		world.setBlock(i + 0, j + 0, k + 5, Block.dirt.blockID);
		world.setBlock(i + 0, j + 0, k + 6, Block.dirt.blockID);
		world.setBlock(i + 0, j + 0, k + 7, Block.dirt.blockID);
		world.setBlock(i + 0, j + 0, k + 8, Block.stone.blockID);
		world.setBlock(i + 0, j + 0, k + 9, Block.stone.blockID);
		world.setBlock(i + 0, j + 0, k + 10, Block.stone.blockID);
		world.setBlock(i + 0, j + 0, k + 11, Block.stone.blockID);
		world.setBlock(i + 0, j + 0, k + 12, Block.stone.blockID);
		world.setBlock(i + 0, j + 0, k + 13, Block.stone.blockID);
		world.setBlock(i + 0, j + 0, k + 14, Block.stone.blockID);
		world.setBlock(i + 0, j + 0, k + 15, Block.dirt.blockID);
		world.setBlock(i + 0, j + 0, k + 16, Block.dirt.blockID);
		world.setBlock(i + 0, j + 0, k + 17, Block.dirt.blockID);
		world.setBlock(i + 0, j + 0, k + 18, Block.dirt.blockID);
		world.setBlock(i + 1, j + 0, k + 3, Block.dirt.blockID);
		world.setBlock(i + 1, j + 0, k + 4, Block.dirt.blockID);
		world.setBlock(i + 1, j + 0, k + 5, Block.dirt.blockID);
		world.setBlock(i + 1, j + 0, k + 6, Block.dirt.blockID);
		world.setBlock(i + 1, j + 0, k + 7, Block.dirt.blockID);
		world.setBlock(i + 1, j + 0, k + 8, Block.dirt.blockID);
		world.setBlock(i + 1, j + 0, k + 9, Block.dirt.blockID);
		world.setBlock(i + 1, j + 0, k + 10, Block.dirt.blockID);
		world.setBlock(i + 1, j + 0, k + 11, Block.dirt.blockID);
		world.setBlock(i + 1, j + 0, k + 12, Block.dirt.blockID);
		world.setBlock(i + 1, j + 0, k + 13, Block.dirt.blockID);
		world.setBlock(i + 1, j + 0, k + 14, Block.dirt.blockID);
		world.setBlock(i + 1, j + 0, k + 15, Block.dirt.blockID);
		world.setBlock(i + 1, j + 0, k + 16, Block.dirt.blockID);
		world.setBlock(i + 1, j + 0, k + 17, Block.dirt.blockID);
		world.setBlock(i + 1, j + 0, k + 18, Block.dirt.blockID);
		world.setBlock(i + 2, j + 0, k + 2, Block.dirt.blockID);
		world.setBlock(i + 2, j + 0, k + 3, Block.dirt.blockID);
		world.setBlock(i + 2, j + 0, k + 4, Block.dirt.blockID);
		world.setBlock(i + 2, j + 0, k + 5, Block.dirt.blockID);
		world.setBlock(i + 2, j + 0, k + 6, Block.dirt.blockID);
		world.setBlock(i + 2, j + 0, k + 7, Block.dirt.blockID);
		world.setBlock(i + 2, j + 0, k + 8, Block.dirt.blockID);
		world.setBlock(i + 2, j + 0, k + 9, Block.dirt.blockID);
		world.setBlock(i + 2, j + 0, k + 10, Block.dirt.blockID);
		world.setBlock(i + 2, j + 0, k + 11, Block.dirt.blockID);
		world.setBlock(i + 2, j + 0, k + 12, Block.dirt.blockID);
		world.setBlock(i + 2, j + 0, k + 13, Block.dirt.blockID);
		world.setBlock(i + 2, j + 0, k + 14, Block.dirt.blockID);
		world.setBlock(i + 2, j + 0, k + 15, Block.dirt.blockID);
		world.setBlock(i + 2, j + 0, k + 16, Block.dirt.blockID);
		world.setBlock(i + 2, j + 0, k + 17, Block.dirt.blockID);
		world.setBlock(i + 2, j + 0, k + 18, Block.dirt.blockID);
		world.setBlock(i + 3, j + 0, k + 1, Block.dirt.blockID);
		world.setBlock(i + 3, j + 0, k + 2, Block.dirt.blockID);
		world.setBlock(i + 3, j + 0, k + 3, Block.dirt.blockID);
		world.setBlock(i + 3, j + 0, k + 4, Block.dirt.blockID);
		world.setBlock(i + 3, j + 0, k + 5, Block.dirt.blockID);
		world.setBlock(i + 3, j + 0, k + 6, Block.dirt.blockID);
		world.setBlock(i + 3, j + 0, k + 7, Block.dirt.blockID);
		world.setBlock(i + 3, j + 0, k + 8, Block.dirt.blockID);
		world.setBlock(i + 3, j + 0, k + 9, Block.dirt.blockID);
		world.setBlock(i + 3, j + 0, k + 10, Block.dirt.blockID);
		world.setBlock(i + 3, j + 0, k + 11, Block.dirt.blockID);
		world.setBlock(i + 3, j + 0, k + 12, Block.dirt.blockID);
		world.setBlock(i + 3, j + 0, k + 13, Block.dirt.blockID);
		world.setBlock(i + 3, j + 0, k + 14, Block.dirt.blockID);
		world.setBlock(i + 3, j + 0, k + 15, Block.dirt.blockID);
		world.setBlock(i + 3, j + 0, k + 16, Block.dirt.blockID);
		world.setBlock(i + 3, j + 0, k + 17, Block.dirt.blockID);
		world.setBlock(i + 3, j + 0, k + 18, Block.dirt.blockID);
		world.setBlock(i + 3, j + 0, k + 19, Block.dirt.blockID);
		world.setBlockMetadataWithNotify(i + 3, j + 6, k + 3, Block.stoneSingleSlab.blockID, 8);
		world.setBlockMetadataWithNotify(i + 3, j + 6, k + 4, Block.stoneSingleSlab.blockID, 8);
		world.setBlockMetadataWithNotify(i + 3, j + 6, k + 5, Block.stoneSingleSlab.blockID, 8);
		world.setBlockMetadataWithNotify(i + 3, j + 6, k + 6, Block.stoneSingleSlab.blockID, 8);
		world.setBlockMetadataWithNotify(i + 3, j + 6, k + 7, Block.stoneSingleSlab.blockID, 8);
		world.setBlockMetadataWithNotify(i + 3, j + 6, k + 8, Block.stoneSingleSlab.blockID, 8);
		world.setBlockMetadataWithNotify(i + 3, j + 6, k + 9, Block.stoneSingleSlab.blockID, 8);
		world.setBlockMetadataWithNotify(i + 3, j + 6, k + 10, Block.stoneSingleSlab.blockID, 8);
		world.setBlockMetadataWithNotify(i + 3, j + 6, k + 11, Block.stoneSingleSlab.blockID, 8);
		world.setBlockMetadataWithNotify(i + 3, j + 6, k + 12, Block.stoneSingleSlab.blockID, 8);
		world.setBlockMetadataWithNotify(i + 3, j + 6, k + 13, Block.stoneSingleSlab.blockID, 8);
		world.setBlockMetadataWithNotify(i + 3, j + 6, k + 14, Block.stoneSingleSlab.blockID, 8);
		world.setBlockMetadataWithNotify(i + 3, j + 6, k + 15, Block.stoneSingleSlab.blockID, 8);
		world.setBlockMetadataWithNotify(i + 3, j + 6, k + 16, Block.stoneSingleSlab.blockID, 8);
		world.setBlock(i + 4, j + 0, k + 0, Block.dirt.blockID);
		world.setBlock(i + 4, j + 0, k + 1, Block.dirt.blockID);
		world.setBlock(i + 4, j + 0, k + 2, Block.dirt.blockID);
		world.setBlock(i + 4, j + 0, k + 3, Block.dirt.blockID);
		world.setBlock(i + 4, j + 0, k + 4, Block.dirt.blockID);
		world.setBlock(i + 4, j + 0, k + 5, Block.dirt.blockID);
		world.setBlock(i + 4, j + 0, k + 6, Block.stoneDoubleSlab.blockID);
		world.setBlock(i + 4, j + 0, k + 7, Block.dirt.blockID);
		world.setBlock(i + 4, j + 0, k + 8, Block.dirt.blockID);
		world.setBlock(i + 4, j + 0, k + 9, Block.dirt.blockID);
		world.setBlock(i + 4, j + 0, k + 10, Block.dirt.blockID);
		world.setBlock(i + 4, j + 0, k + 11, Block.dirt.blockID);
		world.setBlock(i + 4, j + 0, k + 12, Block.dirt.blockID);
		world.setBlock(i + 4, j + 0, k + 13, Block.dirt.blockID);
		world.setBlock(i + 4, j + 0, k + 14, Block.dirt.blockID);
		world.setBlock(i + 4, j + 0, k + 15, Block.dirt.blockID);
		world.setBlock(i + 4, j + 0, k + 16, Block.dirt.blockID);
		world.setBlock(i + 4, j + 0, k + 17, Block.dirt.blockID);
		world.setBlock(i + 4, j + 0, k + 18, Block.dirt.blockID);
		world.setBlock(i + 4, j + 0, k + 19, Block.dirt.blockID);
		world.setBlock(i + 4, j + 0, k + 20, Block.dirt.blockID);
		world.setBlock(i + 4, j + 1, k + 6, Block.stoneSingleSlab.blockID);
		world.setBlock(i + 4, j + 1, k + 13, Block.stoneSingleSlab.blockID);
		world.setBlock(i + 4, j + 6, k + 3, Block.stoneSingleSlab.blockID);
		world.setBlock(i + 4, j + 6, k + 4, Block.stoneDoubleSlab.blockID);
		world.setBlock(i + 4, j + 6, k + 6, Block.stoneDoubleSlab.blockID);
		world.setBlock(i + 4, j + 6, k + 7, Block.stoneDoubleSlab.blockID);
		world.setBlock(i + 4, j + 6, k + 8, Block.stoneDoubleSlab.blockID);
		world.setBlock(i + 4, j + 6, k + 9, Block.stoneDoubleSlab.blockID);
		world.setBlock(i + 4, j + 6, k + 10, Block.stoneDoubleSlab.blockID);
		world.setBlock(i + 4, j + 6, k + 11, Block.stoneDoubleSlab.blockID);
		world.setBlock(i + 4, j + 6, k + 12, Block.stoneDoubleSlab.blockID);
		world.setBlock(i + 4, j + 6, k + 13, Block.stoneDoubleSlab.blockID);
		world.setBlock(i + 4, j + 6, k + 15, Block.stoneDoubleSlab.blockID);
		world.setBlock(i + 4, j + 6, k + 16, Block.stoneSingleSlab.blockID);
		world.setBlock(i + 4, j + 7, k + 3, Block.stoneSingleSlab.blockID);
		world.setBlock(i + 4, j + 7, k + 4, Block.stoneSingleSlab.blockID);
		world.setBlock(i + 4, j + 7, k + 6, Block.stoneSingleSlab.blockID);
		world.setBlock(i + 4, j + 7, k + 7, Block.stoneSingleSlab.blockID);
		world.setBlock(i + 4, j + 7, k + 8, Block.stoneSingleSlab.blockID);
		world.setBlock(i + 4, j + 7, k + 9, Block.stoneSingleSlab.blockID);
		world.setBlock(i + 4, j + 7, k + 10, Block.stoneSingleSlab.blockID);
		world.setBlock(i + 4, j + 7, k + 11, Block.stoneSingleSlab.blockID);
		world.setBlock(i + 4, j + 7, k + 12, Block.stoneSingleSlab.blockID);
		world.setBlock(i + 4, j + 7, k + 13, Block.stoneSingleSlab.blockID);
		world.setBlock(i + 4, j + 7, k + 15, Block.stoneSingleSlab.blockID);
		world.setBlock(i + 4, j + 7, k + 16, Block.stoneSingleSlab.blockID);
		world.setBlock(i + 5, j + 0, k + 0, Block.dirt.blockID);
		world.setBlock(i + 5, j + 0, k + 1, Block.dirt.blockID);
		world.setBlock(i + 5, j + 0, k + 2, Block.dirt.blockID);
		world.setBlock(i + 5, j + 0, k + 3, Block.dirt.blockID);
		world.setBlock(i + 5, j + 0, k + 4, Block.dirt.blockID);
		world.setBlock(i + 5, j + 0, k + 5, Block.dirt.blockID);
		world.setBlock(i + 5, j + 0, k + 6, Block.dirt.blockID);
		world.setBlock(i + 5, j + 0, k + 7, Block.dirt.blockID);
		world.setBlock(i + 5, j + 0, k + 8, Block.dirt.blockID);
		world.setBlock(i + 5, j + 0, k + 9, Block.dirt.blockID);
		world.setBlock(i + 5, j + 0, k + 10, Block.dirt.blockID);
		world.setBlock(i + 5, j + 0, k + 11, Block.dirt.blockID);
		world.setBlock(i + 5, j + 0, k + 12, Block.dirt.blockID);
		world.setBlock(i + 5, j + 0, k + 13, Block.dirt.blockID);
		world.setBlock(i + 5, j + 0, k + 14, Block.dirt.blockID);
		world.setBlock(i + 5, j + 0, k + 15, Block.dirt.blockID);
		world.setBlock(i + 5, j + 0, k + 16, Block.dirt.blockID);
		world.setBlock(i + 5, j + 0, k + 17, Block.dirt.blockID);
		world.setBlock(i + 5, j + 0, k + 18, Block.dirt.blockID);
		world.setBlock(i + 5, j + 0, k + 19, Block.dirt.blockID);
		world.setBlock(i + 5, j + 0, k + 20, Block.dirt.blockID);
		world.setBlock(i + 5, j + 1, k + 5, Block.blockIron.blockID);
		world.setBlock(i + 5, j + 1, k + 6, Block.fence.blockID);
		world.setBlock(i + 5, j + 1, k + 7, Block.blockIron.blockID);
		world.setBlock(i + 5, j + 1, k + 12, Block.blockIron.blockID);
		world.setBlock(i + 5, j + 1, k + 13, Block.fence.blockID);
		world.setBlock(i + 5, j + 1, k + 14, Block.blockIron.blockID);
		world.setBlock(i + 5, j + 2, k + 5, Block.blockIron.blockID);
		world.setBlock(i + 5, j + 2, k + 6, Block.fence.blockID);
		world.setBlock(i + 5, j + 2, k + 7, Block.blockIron.blockID);
		world.setBlock(i + 5, j + 2, k + 12, Block.blockIron.blockID);
		world.setBlock(i + 5, j + 2, k + 13, Block.fence.blockID);
		world.setBlock(i + 5, j + 2, k + 14, Block.blockIron.blockID);
		world.setBlockMetadataWithNotify(i + 5, j + 3, k + 5, -111, 3);
		world.setBlock(i + 5, j + 3, k + 6, Block.fence.blockID);
		world.setBlockMetadataWithNotify(i + 5, j + 3, k + 7, -111, 1);
		world.setBlockMetadataWithNotify(i + 5, j + 3, k + 12, -111, 3);
		world.setBlock(i + 5, j + 3, k + 13, Block.fence.blockID);
		world.setBlockMetadataWithNotify(i + 5, j + 3, k + 14, -111, 1);
		world.setBlock(i + 5, j + 4, k + 6, Block.fence.blockID);
		world.setBlock(i + 5, j + 4, k + 13, Block.fence.blockID);
		world.setBlockMetadataWithNotify(i + 5, j + 5, k + 3, Block.stoneSingleSlab.blockID, 8);
		world.setBlockMetadataWithNotify(i + 5, j + 5, k + 4, Block.stoneSingleSlab.blockID, 8);
		world.setBlock(i + 5, j + 5, k + 6, Block.fence.blockID);
		world.setBlockMetadataWithNotify(i + 5, j + 5, k + 7, Block.stoneSingleSlab.blockID, 8);
		world.setBlockMetadataWithNotify(i + 5, j + 5, k + 8, Block.stoneSingleSlab.blockID, 8);
		world.setBlockMetadataWithNotify(i + 5, j + 5, k + 9, Block.stoneSingleSlab.blockID, 8);
		world.setBlockMetadataWithNotify(i + 5, j + 5, k + 10, Block.stoneSingleSlab.blockID, 8);
		world.setBlockMetadataWithNotify(i + 5, j + 5, k + 11, Block.stoneSingleSlab.blockID, 8);
		world.setBlock(i + 5, j + 5, k + 13, Block.fence.blockID);
		world.setBlockMetadataWithNotify(i + 5, j + 5, k + 15, Block.stoneSingleSlab.blockID, 8);
		world.setBlockMetadataWithNotify(i + 5, j + 5, k + 16, Block.stoneSingleSlab.blockID, 8);
		world.setBlock(i + 5, j + 6, k + 4, Block.stoneDoubleSlab.blockID);
		world.setBlock(i + 5, j + 6, k + 5, Block.glowStone.blockID);
		world.setBlock(i + 5, j + 6, k + 6, Block.stoneDoubleSlab.blockID);
		world.setBlock(i + 5, j + 6, k + 7, Block.glowStone.blockID);
		world.setBlock(i + 5, j + 6, k + 8, Block.stoneDoubleSlab.blockID);
		world.setBlock(i + 5, j + 6, k + 9, Block.stoneDoubleSlab.blockID);
		world.setBlock(i + 5, j + 6, k + 10, Block.stoneDoubleSlab.blockID);
		world.setBlock(i + 5, j + 6, k + 11, Block.stoneDoubleSlab.blockID);
		world.setBlock(i + 5, j + 6, k + 12, Block.glowStone.blockID);
		world.setBlock(i + 5, j + 6, k + 13, Block.stoneDoubleSlab.blockID);
		world.setBlock(i + 5, j + 6, k + 14, Block.glowStone.blockID);
		world.setBlock(i + 5, j + 6, k + 15, Block.stoneDoubleSlab.blockID);
		world.setBlockMetadataWithNotify(i + 5, j + 7, k + 3, Block.stoneSingleSlab.blockID, 8);
		world.setBlock(i + 5, j + 7, k + 4, Block.stoneDoubleSlab.blockID);
		world.setBlock(i + 5, j + 7, k + 5, Block.stoneDoubleSlab.blockID);
		world.setBlock(i + 5, j + 7, k + 6, Block.stoneDoubleSlab.blockID);
		world.setBlock(i + 5, j + 7, k + 7, Block.stoneDoubleSlab.blockID);
		world.setBlock(i + 5, j + 7, k + 8, Block.stoneDoubleSlab.blockID);
		world.setBlock(i + 5, j + 7, k + 9, Block.stoneDoubleSlab.blockID);
		world.setBlock(i + 5, j + 7, k + 10, Block.stoneDoubleSlab.blockID);
		world.setBlock(i + 5, j + 7, k + 11, Block.stoneDoubleSlab.blockID);
		world.setBlock(i + 5, j + 7, k + 12, Block.stoneDoubleSlab.blockID);
		world.setBlock(i + 5, j + 7, k + 13, Block.stoneDoubleSlab.blockID);
		world.setBlock(i + 5, j + 7, k + 14, Block.stoneDoubleSlab.blockID);
		world.setBlock(i + 5, j + 7, k + 15, Block.stoneDoubleSlab.blockID);
		world.setBlockMetadataWithNotify(i + 5, j + 7, k + 16, Block.stoneSingleSlab.blockID, 8);
		world.setBlock(i + 6, j + 0, k + 0, Block.dirt.blockID);
		world.setBlock(i + 6, j + 0, k + 1, Block.dirt.blockID);
		world.setBlock(i + 6, j + 0, k + 2, Block.dirt.blockID);
		world.setBlock(i + 6, j + 0, k + 3, Block.dirt.blockID);
		world.setBlock(i + 6, j + 0, k + 4, Block.dirt.blockID);
		world.setBlock(i + 6, j + 0, k + 5, Block.dirt.blockID);
		world.setBlock(i + 6, j + 0, k + 6, Block.dirt.blockID);
		world.setBlock(i + 6, j + 0, k + 7, Block.dirt.blockID);
		world.setBlock(i + 6, j + 0, k + 8, Block.dirt.blockID);
		world.setBlock(i + 6, j + 0, k + 9, Block.dirt.blockID);
		world.setBlock(i + 6, j + 0, k + 10, Block.dirt.blockID);
		world.setBlock(i + 6, j + 0, k + 11, Block.dirt.blockID);
		world.setBlock(i + 6, j + 0, k + 12, Block.dirt.blockID);
		world.setBlock(i + 6, j + 0, k + 13, Block.dirt.blockID);
		world.setBlock(i + 6, j + 0, k + 14, Block.dirt.blockID);
		world.setBlock(i + 6, j + 0, k + 15, Block.dirt.blockID);
		world.setBlock(i + 6, j + 0, k + 16, Block.dirt.blockID);
		world.setBlock(i + 6, j + 0, k + 17, Block.dirt.blockID);
		world.setBlock(i + 6, j + 0, k + 18, Block.dirt.blockID);
		world.setBlock(i + 6, j + 0, k + 19, Block.dirt.blockID);
		world.setBlock(i + 6, j + 0, k + 20, Block.dirt.blockID);
		world.setBlock(i + 6, j + 1, k + 6, Block.stoneSingleSlab.blockID);
		world.setBlock(i + 6, j + 1, k + 13, Block.stoneSingleSlab.blockID);
		world.setBlock(i + 6, j + 6, k + 3, Block.stoneSingleSlab.blockID);
		world.setBlock(i + 6, j + 6, k + 4, Block.stoneDoubleSlab.blockID);
		world.setBlock(i + 6, j + 6, k + 6, Block.stoneDoubleSlab.blockID);
		world.setBlock(i + 6, j + 6, k + 7, Block.stoneDoubleSlab.blockID);
		world.setBlock(i + 6, j + 6, k + 8, Block.stoneDoubleSlab.blockID);
		world.setBlock(i + 6, j + 6, k + 9, Block.stoneDoubleSlab.blockID);
		world.setBlock(i + 6, j + 6, k + 10, Block.stoneDoubleSlab.blockID);
		world.setBlock(i + 6, j + 6, k + 11, Block.stoneDoubleSlab.blockID);
		world.setBlock(i + 6, j + 6, k + 12, Block.stoneDoubleSlab.blockID);
		world.setBlock(i + 6, j + 6, k + 13, Block.stoneDoubleSlab.blockID);
		world.setBlock(i + 6, j + 6, k + 15, Block.stoneDoubleSlab.blockID);
		world.setBlock(i + 6, j + 6, k + 16, Block.stoneSingleSlab.blockID);
		world.setBlock(i + 6, j + 7, k + 3, Block.stoneSingleSlab.blockID);
		world.setBlock(i + 6, j + 7, k + 4, Block.stoneSingleSlab.blockID);
		world.setBlock(i + 6, j + 7, k + 6, Block.stoneSingleSlab.blockID);
		world.setBlock(i + 6, j + 7, k + 7, Block.stoneSingleSlab.blockID);
		world.setBlock(i + 6, j + 7, k + 8, Block.stoneSingleSlab.blockID);
		world.setBlock(i + 6, j + 7, k + 9, Block.stoneSingleSlab.blockID);
		world.setBlock(i + 6, j + 7, k + 10, Block.stoneSingleSlab.blockID);
		world.setBlock(i + 6, j + 7, k + 11, Block.stoneSingleSlab.blockID);
		world.setBlock(i + 6, j + 7, k + 12, Block.stoneSingleSlab.blockID);
		world.setBlock(i + 6, j + 7, k + 13, Block.stoneSingleSlab.blockID);
		world.setBlock(i + 6, j + 7, k + 15, Block.stoneSingleSlab.blockID);
		world.setBlock(i + 6, j + 7, k + 16, Block.stoneSingleSlab.blockID);
		world.setBlock(i + 7, j + 0, k + 0, Block.dirt.blockID);
		world.setBlock(i + 7, j + 0, k + 1, Block.dirt.blockID);
		world.setBlock(i + 7, j + 0, k + 2, Block.dirt.blockID);
		world.setBlock(i + 7, j + 0, k + 3, Block.dirt.blockID);
		world.setBlock(i + 7, j + 0, k + 4, Block.dirt.blockID);
		world.setBlock(i + 7, j + 0, k + 5, Block.dirt.blockID);
		world.setBlock(i + 7, j + 0, k + 6, Block.dirt.blockID);
		world.setBlock(i + 7, j + 0, k + 7, Block.dirt.blockID);
		world.setBlock(i + 7, j + 0, k + 8, Block.dirt.blockID);
		world.setBlock(i + 7, j + 0, k + 9, Block.dirt.blockID);
		world.setBlock(i + 7, j + 0, k + 10, Block.dirt.blockID);
		world.setBlock(i + 7, j + 0, k + 11, Block.dirt.blockID);
		world.setBlock(i + 7, j + 0, k + 12, Block.dirt.blockID);
		world.setBlock(i + 7, j + 0, k + 13, Block.dirt.blockID);
		world.setBlock(i + 7, j + 0, k + 14, Block.dirt.blockID);
		world.setBlock(i + 7, j + 0, k + 15, Block.dirt.blockID);
		world.setBlock(i + 7, j + 0, k + 16, Block.dirt.blockID);
		world.setBlock(i + 7, j + 0, k + 17, Block.dirt.blockID);
		world.setBlock(i + 7, j + 0, k + 18, Block.dirt.blockID);
		world.setBlock(i + 7, j + 0, k + 19, Block.dirt.blockID);
		world.setBlock(i + 7, j + 0, k + 20, Block.dirt.blockID);
		world.setBlockMetadataWithNotify(i + 7, j + 6, k + 3, Block.stoneSingleSlab.blockID, 8);
		world.setBlockMetadataWithNotify(i + 7, j + 6, k + 4, Block.stoneSingleSlab.blockID, 8);
		world.setBlockMetadataWithNotify(i + 7, j + 6, k + 5, Block.stoneSingleSlab.blockID, 8);
		world.setBlockMetadataWithNotify(i + 7, j + 6, k + 6, Block.stoneSingleSlab.blockID, 8);
		world.setBlockMetadataWithNotify(i + 7, j + 6, k + 7, Block.stoneSingleSlab.blockID, 8);
		world.setBlockMetadataWithNotify(i + 7, j + 6, k + 8, Block.stoneSingleSlab.blockID, 8);
		world.setBlockMetadataWithNotify(i + 7, j + 6, k + 9, Block.stoneSingleSlab.blockID, 8);
		world.setBlockMetadataWithNotify(i + 7, j + 6, k + 10, Block.stoneSingleSlab.blockID, 8);
		world.setBlockMetadataWithNotify(i + 7, j + 6, k + 11, Block.stoneSingleSlab.blockID, 8);
		world.setBlockMetadataWithNotify(i + 7, j + 6, k + 12, Block.stoneSingleSlab.blockID, 8);
		world.setBlockMetadataWithNotify(i + 7, j + 6, k + 13, Block.stoneSingleSlab.blockID, 8);
		world.setBlockMetadataWithNotify(i + 7, j + 6, k + 14, Block.stoneSingleSlab.blockID, 8);
		world.setBlockMetadataWithNotify(i + 7, j + 6, k + 15, Block.stoneSingleSlab.blockID, 8);
		world.setBlockMetadataWithNotify(i + 7, j + 6, k + 16, Block.stoneSingleSlab.blockID, 8);
		world.setBlock(i + 8, j + 0, k + 0, Block.dirt.blockID);
		world.setBlock(i + 8, j + 0, k + 1, Block.dirt.blockID);
		world.setBlock(i + 8, j + 0, k + 2, Block.dirt.blockID);
		world.setBlock(i + 8, j + 0, k + 3, Block.dirt.blockID);
		world.setBlock(i + 8, j + 0, k + 4, Block.dirt.blockID);
		world.setBlock(i + 8, j + 0, k + 5, Block.dirt.blockID);
		world.setBlock(i + 8, j + 0, k + 6, Block.dirt.blockID);
		world.setBlock(i + 8, j + 0, k + 7, Block.dirt.blockID);
		world.setBlock(i + 8, j + 0, k + 8, Block.dirt.blockID);
		world.setBlock(i + 8, j + 0, k + 9, Block.dirt.blockID);
		world.setBlock(i + 8, j + 0, k + 10, Block.dirt.blockID);
		world.setBlock(i + 8, j + 0, k + 11, Block.dirt.blockID);
		world.setBlock(i + 8, j + 0, k + 12, Block.dirt.blockID);
		world.setBlock(i + 8, j + 0, k + 13, Block.dirt.blockID);
		world.setBlock(i + 8, j + 0, k + 14, Block.dirt.blockID);
		world.setBlock(i + 8, j + 0, k + 15, Block.dirt.blockID);
		world.setBlock(i + 8, j + 0, k + 16, Block.dirt.blockID);
		world.setBlock(i + 8, j + 0, k + 17, Block.dirt.blockID);
		world.setBlock(i + 8, j + 0, k + 18, Block.dirt.blockID);
		world.setBlock(i + 8, j + 0, k + 19, Block.dirt.blockID);
		world.setBlock(i + 8, j + 0, k + 20, Block.dirt.blockID);
		world.setBlock(i + 9, j + 0, k + 0, Block.dirt.blockID);
		world.setBlock(i + 9, j + 0, k + 1, Block.dirt.blockID);
		world.setBlock(i + 9, j + 0, k + 2, Block.dirt.blockID);
		world.setBlock(i + 9, j + 0, k + 3, Block.dirt.blockID);
		world.setBlock(i + 9, j + 0, k + 4, Block.dirt.blockID);
		world.setBlock(i + 9, j + 0, k + 5, Block.dirt.blockID);
		world.setBlock(i + 9, j + 0, k + 6, Block.dirt.blockID);
		world.setBlock(i + 9, j + 0, k + 7, Block.dirt.blockID);
		world.setBlock(i + 9, j + 0, k + 8, Block.dirt.blockID);
		world.setBlock(i + 9, j + 0, k + 9, Block.dirt.blockID);
		world.setBlock(i + 9, j + 0, k + 10, Block.dirt.blockID);
		world.setBlock(i + 9, j + 0, k + 11, Block.dirt.blockID);
		world.setBlock(i + 9, j + 0, k + 12, Block.dirt.blockID);
		world.setBlock(i + 9, j + 0, k + 13, Block.dirt.blockID);
		world.setBlock(i + 9, j + 0, k + 14, Block.dirt.blockID);
		world.setBlock(i + 9, j + 0, k + 15, Block.dirt.blockID);
		world.setBlock(i + 9, j + 0, k + 16, Block.dirt.blockID);
		world.setBlock(i + 9, j + 0, k + 17, Block.dirt.blockID);
		world.setBlock(i + 9, j + 0, k + 18, Block.dirt.blockID);
		world.setBlock(i + 9, j + 0, k + 19, Block.dirt.blockID);
		world.setBlock(i + 9, j + 0, k + 20, Block.dirt.blockID);
		world.setBlock(i + 10, j + 0, k + 0, Block.dirt.blockID);
		world.setBlock(i + 10, j + 0, k + 1, Block.dirt.blockID);
		world.setBlock(i + 10, j + 0, k + 2, Block.dirt.blockID);
		world.setBlock(i + 10, j + 0, k + 3, Block.dirt.blockID);
		world.setBlock(i + 10, j + 0, k + 4, Block.dirt.blockID);
		world.setBlock(i + 10, j + 0, k + 5, Block.dirt.blockID);
		world.setBlock(i + 10, j + 0, k + 6, Block.dirt.blockID);
		world.setBlock(i + 10, j + 0, k + 7, Block.dirt.blockID);
		world.setBlock(i + 10, j + 0, k + 8, Block.dirt.blockID);
		world.setBlock(i + 10, j + 0, k + 9, Block.dirt.blockID);
		world.setBlock(i + 10, j + 0, k + 10, Block.dirt.blockID);
		world.setBlock(i + 10, j + 0, k + 11, Block.dirt.blockID);
		world.setBlock(i + 10, j + 0, k + 12, Block.dirt.blockID);
		world.setBlock(i + 10, j + 0, k + 13, Block.dirt.blockID);
		world.setBlock(i + 10, j + 0, k + 14, Block.dirt.blockID);
		world.setBlock(i + 10, j + 0, k + 15, Block.dirt.blockID);
		world.setBlock(i + 10, j + 0, k + 16, Block.dirt.blockID);
		world.setBlock(i + 10, j + 0, k + 17, Block.dirt.blockID);
		world.setBlock(i + 10, j + 0, k + 18, Block.dirt.blockID);
		world.setBlock(i + 10, j + 0, k + 19, Block.dirt.blockID);
		world.setBlock(i + 10, j + 0, k + 20, Block.dirt.blockID);
		world.setBlock(i + 11, j + 0, k + 0, Block.dirt.blockID);
		world.setBlock(i + 11, j + 0, k + 1, Block.dirt.blockID);
		world.setBlock(i + 11, j + 0, k + 2, Block.dirt.blockID);
		world.setBlock(i + 11, j + 0, k + 3, Block.dirt.blockID);
		world.setBlock(i + 11, j + 0, k + 4, Block.dirt.blockID);
		world.setBlock(i + 11, j + 0, k + 5, Block.dirt.blockID);
		world.setBlock(i + 11, j + 0, k + 6, Block.dirt.blockID);
		world.setBlock(i + 11, j + 0, k + 7, Block.dirt.blockID);
		world.setBlock(i + 11, j + 0, k + 8, Block.dirt.blockID);
		world.setBlock(i + 11, j + 0, k + 9, Block.dirt.blockID);
		world.setBlock(i + 11, j + 0, k + 10, Block.dirt.blockID);
		world.setBlock(i + 11, j + 0, k + 11, Block.dirt.blockID);
		world.setBlock(i + 11, j + 0, k + 12, Block.dirt.blockID);
		world.setBlock(i + 11, j + 0, k + 13, Block.dirt.blockID);
		world.setBlock(i + 11, j + 0, k + 14, Block.dirt.blockID);
		world.setBlock(i + 11, j + 0, k + 15, Block.dirt.blockID);
		world.setBlock(i + 11, j + 0, k + 16, Block.dirt.blockID);
		world.setBlock(i + 11, j + 0, k + 17, Block.dirt.blockID);
		world.setBlock(i + 11, j + 0, k + 18, Block.dirt.blockID);
		world.setBlock(i + 11, j + 0, k + 19, Block.dirt.blockID);
		world.setBlock(i + 11, j + 0, k + 20, Block.dirt.blockID);
		world.setBlock(i + 12, j + 0, k + 0, Block.dirt.blockID);
		world.setBlock(i + 12, j + 0, k + 1, Block.dirt.blockID);
		world.setBlock(i + 12, j + 0, k + 2, Block.dirt.blockID);
		world.setBlock(i + 12, j + 0, k + 3, Block.dirt.blockID);
		world.setBlock(i + 12, j + 0, k + 4, Block.dirt.blockID);
		world.setBlock(i + 12, j + 0, k + 5, Block.dirt.blockID);
		world.setBlock(i + 12, j + 0, k + 6, Block.dirt.blockID);
		world.setBlock(i + 12, j + 0, k + 7, Block.dirt.blockID);
		world.setBlock(i + 12, j + 0, k + 8, Block.dirt.blockID);
		world.setBlock(i + 12, j + 0, k + 9, Block.dirt.blockID);
		world.setBlock(i + 12, j + 0, k + 10, Block.dirt.blockID);
		world.setBlock(i + 12, j + 0, k + 11, Block.dirt.blockID);
		world.setBlock(i + 12, j + 0, k + 12, Block.dirt.blockID);
		world.setBlock(i + 12, j + 0, k + 13, Block.dirt.blockID);
		world.setBlock(i + 12, j + 0, k + 14, Block.dirt.blockID);
		world.setBlock(i + 12, j + 0, k + 15, Block.dirt.blockID);
		world.setBlock(i + 12, j + 0, k + 16, Block.dirt.blockID);
		world.setBlock(i + 12, j + 0, k + 17, Block.dirt.blockID);
		world.setBlock(i + 12, j + 0, k + 18, Block.dirt.blockID);
		world.setBlock(i + 12, j + 0, k + 19, Block.dirt.blockID);
		world.setBlock(i + 12, j + 0, k + 20, Block.dirt.blockID);
		world.setBlock(i + 12, j + 1, k + 6, Block.stoneSingleSlab.blockID);
		world.setBlockMetadataWithNotify(i + 12, j + 5, k + 15, Block.stoneSingleSlab.blockID, 8);
		world.setBlock(i + 12, j + 6, k + 10, Block.stoneDoubleSlab.blockID);
		world.setBlock(i + 12, j + 6, k + 11, Block.stoneSingleSlab.blockID);
		world.setBlock(i + 12, j + 6, k + 12, Block.stoneSingleSlab.blockID);
		world.setBlock(i + 12, j + 6, k + 13, Block.stoneSingleSlab.blockID);
		world.setBlock(i + 12, j + 6, k + 14, Block.stoneSingleSlab.blockID);
		world.setBlockMetadataWithNotify(i + 12, j + 7, k + 3, Block.stoneSingleSlab.blockID, 8);
		world.setBlock(i + 12, j + 7, k + 4, Block.stoneSingleSlab.blockID);
		world.setBlock(i + 12, j + 7, k + 5, Block.stoneSingleSlab.blockID);
		world.setBlock(i + 12, j + 7, k + 6, Block.stoneSingleSlab.blockID);
		world.setBlock(i + 12, j + 7, k + 7, Block.stoneSingleSlab.blockID);
		world.setBlock(i + 12, j + 7, k + 8, Block.stoneSingleSlab.blockID);
		world.setBlock(i + 12, j + 7, k + 9, Block.stoneSingleSlab.blockID);
		world.setBlock(i + 13, j + 0, k + 0, Block.dirt.blockID);
		world.setBlock(i + 13, j + 0, k + 1, Block.dirt.blockID);
		world.setBlock(i + 13, j + 0, k + 2, Block.dirt.blockID);
		world.setBlock(i + 13, j + 0, k + 3, Block.dirt.blockID);
		world.setBlock(i + 13, j + 0, k + 4, Block.dirt.blockID);
		world.setBlock(i + 13, j + 0, k + 5, Block.dirt.blockID);
		world.setBlock(i + 13, j + 0, k + 6, Block.dirt.blockID);
		world.setBlock(i + 13, j + 0, k + 7, Block.dirt.blockID);
		world.setBlock(i + 13, j + 0, k + 8, Block.dirt.blockID);
		world.setBlock(i + 13, j + 0, k + 9, Block.dirt.blockID);
		world.setBlock(i + 13, j + 0, k + 10, Block.dirt.blockID);
		world.setBlock(i + 13, j + 0, k + 11, Block.dirt.blockID);
		world.setBlock(i + 13, j + 0, k + 12, Block.dirt.blockID);
		world.setBlock(i + 13, j + 0, k + 13, Block.dirt.blockID);
		world.setBlock(i + 13, j + 0, k + 14, Block.dirt.blockID);
		world.setBlock(i + 13, j + 0, k + 15, Block.dirt.blockID);
		world.setBlock(i + 13, j + 0, k + 16, Block.dirt.blockID);
		world.setBlock(i + 13, j + 0, k + 17, Block.dirt.blockID);
		world.setBlock(i + 13, j + 0, k + 18, Block.dirt.blockID);
		world.setBlock(i + 13, j + 0, k + 19, Block.dirt.blockID);
		world.setBlock(i + 13, j + 0, k + 20, Block.dirt.blockID);
		world.setBlock(i + 13, j + 1, k + 5, Block.stoneDoubleSlab.blockID);
		world.setBlock(i + 13, j + 1, k + 6, Block.stoneDoubleSlab.blockID);
		world.setBlock(i + 13, j + 1, k + 7, Block.stoneDoubleSlab.blockID);
		world.setBlock(i + 13, j + 1, k + 8, Block.stoneDoubleSlab.blockID);
		world.setBlock(i + 13, j + 1, k + 9, Block.stoneDoubleSlab.blockID);
		world.setBlock(i + 13, j + 1, k + 10, Block.stoneDoubleSlab.blockID);
		world.setBlock(i + 13, j + 1, k + 11, Block.stoneDoubleSlab.blockID);
		world.setBlock(i + 13, j + 1, k + 14, Block.stoneDoubleSlab.blockID);
		world.setBlock(i + 13, j + 2, k + 5, Block.stone.blockID);
		world.setBlock(i + 13, j + 2, k + 7, Block.stone.blockID);
		world.setBlock(i + 13, j + 2, k + 8, Block.stone.blockID);
		world.setBlock(i + 13, j + 2, k + 9, Block.stone.blockID);
		world.setBlock(i + 13, j + 2, k + 10, Block.stone.blockID);
		world.setBlock(i + 13, j + 2, k + 11, Block.stone.blockID);
		world.setBlock(i + 13, j + 2, k + 14, Block.stone.blockID);
		world.setBlock(i + 13, j + 3, k + 5, Block.stone.blockID);
		world.setBlock(i + 13, j + 3, k + 7, Block.stone.blockID);
		world.setBlock(i + 13, j + 3, k + 8, Block.glass.blockID);
		world.setBlock(i + 13, j + 3, k + 9, Block.glass.blockID);
		world.setBlock(i + 13, j + 3, k + 10, Block.stone.blockID);
		world.setBlock(i + 13, j + 3, k + 11, Block.stone.blockID);
		world.setBlockMetadataWithNotify(i + 13, j + 3, k + 12, Block.stoneSingleSlab.blockID, 8);
		world.setBlockMetadataWithNotify(i + 13, j + 3, k + 13, Block.stoneSingleSlab.blockID, 8);
		world.setBlock(i + 13, j + 3, k + 14, Block.stone.blockID);
		world.setBlock(i + 13, j + 4, k + 5, Block.stone.blockID);
		world.setBlock(i + 13, j + 4, k + 6, Block.stone.blockID);
		world.setBlock(i + 13, j + 4, k + 7, Block.stone.blockID);
		world.setBlock(i + 13, j + 4, k + 8, Block.stone.blockID);
		world.setBlock(i + 13, j + 4, k + 9, Block.stone.blockID);
		world.setBlock(i + 13, j + 4, k + 10, Block.stone.blockID);
		world.setBlock(i + 13, j + 4, k + 11, Block.stone.blockID);
		world.setBlock(i + 13, j + 4, k + 12, Block.stone.blockID);
		world.setBlock(i + 13, j + 4, k + 13, Block.stone.blockID);
		world.setBlock(i + 13, j + 4, k + 14, Block.stone.blockID);
		world.setBlock(i + 13, j + 5, k + 5, Block.stone.blockID);
		world.setBlock(i + 13, j + 5, k + 6, Block.stone.blockID);
		world.setBlock(i + 13, j + 5, k + 7, Block.stone.blockID);
		world.setBlock(i + 13, j + 5, k + 8, Block.stone.blockID);
		world.setBlock(i + 13, j + 5, k + 9, Block.stone.blockID);
		world.setBlock(i + 13, j + 5, k + 10, Block.stone.blockID);
		world.setBlock(i + 13, j + 5, k + 11, Block.stone.blockID);
		world.setBlock(i + 13, j + 5, k + 12, Block.stone.blockID);
		world.setBlock(i + 13, j + 5, k + 13, Block.stone.blockID);
		world.setBlock(i + 13, j + 5, k + 14, Block.stone.blockID);
		world.setBlockMetadataWithNotify(i + 13, j + 5, k + 15, Block.stoneSingleSlab.blockID, 8);
		world.setBlock(i + 13, j + 6, k + 4, Block.stone.blockID);
		world.setBlock(i + 13, j + 6, k + 5, Block.stone.blockID);
		world.setBlock(i + 13, j + 6, k + 6, Block.stone.blockID);
		world.setBlock(i + 13, j + 6, k + 7, Block.stone.blockID);
		world.setBlock(i + 13, j + 6, k + 8, Block.stone.blockID);
		world.setBlock(i + 13, j + 6, k + 9, Block.stone.blockID);
		world.setBlock(i + 13, j + 6, k + 10, Block.stoneDoubleSlab.blockID);
		world.setBlock(i + 13, j + 6, k + 11, Block.stoneSingleSlab.blockID);
		world.setBlock(i + 13, j + 6, k + 12, Block.stoneSingleSlab.blockID);
		world.setBlock(i + 13, j + 6, k + 13, Block.stoneSingleSlab.blockID);
		world.setBlock(i + 13, j + 6, k + 14, Block.stoneSingleSlab.blockID);
		world.setBlockMetadataWithNotify(i + 13, j + 7, k + 3, Block.stoneSingleSlab.blockID, 8);
		world.setBlock(i + 13, j + 7, k + 4, Block.stoneSingleSlab.blockID);
		world.setBlock(i + 13, j + 7, k + 5, Block.stoneSingleSlab.blockID);
		world.setBlock(i + 13, j + 7, k + 6, Block.stoneSingleSlab.blockID);
		world.setBlock(i + 13, j + 7, k + 7, Block.stoneSingleSlab.blockID);
		world.setBlock(i + 13, j + 7, k + 8, Block.stoneSingleSlab.blockID);
		world.setBlock(i + 13, j + 7, k + 9, Block.stoneSingleSlab.blockID);
		world.setBlock(i + 14, j + 0, k + 0, Block.dirt.blockID);
		world.setBlock(i + 14, j + 0, k + 1, Block.dirt.blockID);
		world.setBlock(i + 14, j + 0, k + 2, Block.dirt.blockID);
		world.setBlock(i + 14, j + 0, k + 3, Block.dirt.blockID);
		world.setBlock(i + 14, j + 0, k + 4, Block.dirt.blockID);
		world.setBlock(i + 14, j + 0, k + 5, Block.dirt.blockID);
		world.setBlock(i + 14, j + 0, k + 6, Block.dirt.blockID);
		world.setBlock(i + 14, j + 0, k + 7, Block.dirt.blockID);
		world.setBlock(i + 14, j + 0, k + 8, Block.dirt.blockID);
		world.setBlock(i + 14, j + 0, k + 9, Block.dirt.blockID);
		world.setBlock(i + 14, j + 0, k + 10, Block.dirt.blockID);
		world.setBlock(i + 14, j + 0, k + 11, Block.dirt.blockID);
		world.setBlock(i + 14, j + 0, k + 12, Block.dirt.blockID);
		world.setBlock(i + 14, j + 0, k + 13, Block.dirt.blockID);
		world.setBlock(i + 14, j + 0, k + 14, Block.dirt.blockID);
		world.setBlock(i + 14, j + 0, k + 15, Block.dirt.blockID);
		world.setBlock(i + 14, j + 0, k + 16, Block.dirt.blockID);
		world.setBlock(i + 14, j + 0, k + 17, Block.dirt.blockID);
		world.setBlock(i + 14, j + 0, k + 18, Block.dirt.blockID);
		world.setBlock(i + 14, j + 0, k + 19, Block.dirt.blockID);
		world.setBlock(i + 14, j + 0, k + 20, Block.dirt.blockID);
		world.setBlock(i + 14, j + 1, k + 5, Block.stoneDoubleSlab.blockID);
		world.setBlock(i + 14, j + 1, k + 6, Block.stoneDoubleSlab.blockID);
		world.setBlock(i + 14, j + 1, k + 7, Block.stoneDoubleSlab.blockID);
		world.setBlock(i + 14, j + 1, k + 8, Block.stoneDoubleSlab.blockID);
		world.setBlock(i + 14, j + 1, k + 9, Block.stoneDoubleSlab.blockID);
		world.setBlock(i + 14, j + 1, k + 10, Block.stoneDoubleSlab.blockID);
		world.setBlock(i + 14, j + 1, k + 11, Block.stoneDoubleSlab.blockID);
		world.setBlock(i + 14, j + 1, k + 14, Block.stoneDoubleSlab.blockID);
		world.setBlock(i + 14, j + 2, k + 5, Block.stone.blockID);
		world.setBlockMetadataWithNotify(i + 14, j + 2, k + 9, Block.stoneSingleSlab.blockID, 8);
		world.setBlock(i + 14, j + 2, k + 11, Block.stone.blockID);
		world.setBlock(i + 14, j + 2, k + 14, Block.stone.blockID);
		world.setBlock(i + 14, j + 3, k + 5, Block.stone.blockID);
		world.setBlock(i + 14, j + 3, k + 11, Block.stone.blockID);
		world.setBlock(i + 14, j + 3, k + 14, Block.stone.blockID);
		world.setBlock(i + 14, j + 4, k + 5, Block.stone.blockID);
		world.setBlock(i + 14, j + 4, k + 11, Block.stone.blockID);
		world.setBlock(i + 14, j + 4, k + 14, Block.stone.blockID);
		world.setBlock(i + 14, j + 5, k + 5, Block.stone.blockID);
		world.setBlock(i + 14, j + 5, k + 11, Block.stone.blockID);
		world.setBlock(i + 14, j + 5, k + 12, Block.glowStone.blockID);
		world.setBlock(i + 14, j + 5, k + 13, Block.glowStone.blockID);
		world.setBlock(i + 14, j + 5, k + 14, Block.stone.blockID);
		world.setBlockMetadataWithNotify(i + 14, j + 5, k + 15, Block.stoneSingleSlab.blockID, 8);
		world.setBlock(i + 14, j + 6, k + 4, Block.stone.blockID);
		world.setBlock(i + 14, j + 6, k + 5, Block.stone.blockID);
		world.setBlock(i + 14, j + 6, k + 9, Block.stoneDoubleSlab.blockID);
		world.setBlock(i + 14, j + 6, k + 10, Block.stoneDoubleSlab.blockID);
		world.setBlock(i + 14, j + 6, k + 11, Block.stoneSingleSlab.blockID);
		world.setBlock(i + 14, j + 6, k + 12, Block.stoneSingleSlab.blockID);
		world.setBlock(i + 14, j + 6, k + 13, Block.stoneSingleSlab.blockID);
		world.setBlock(i + 14, j + 6, k + 14, Block.stoneSingleSlab.blockID);
		world.setBlockMetadataWithNotify(i + 14, j + 7, k + 3, Block.stoneSingleSlab.blockID, 8);
		world.setBlock(i + 14, j + 7, k + 4, Block.stoneSingleSlab.blockID);
		world.setBlock(i + 14, j + 7, k + 5, Block.stoneSingleSlab.blockID);
		world.setBlock(i + 14, j + 7, k + 6, Block.stoneSingleSlab.blockID);
		world.setBlock(i + 14, j + 7, k + 7, Block.stoneSingleSlab.blockID);
		world.setBlock(i + 14, j + 7, k + 8, Block.stoneSingleSlab.blockID);
		world.setBlock(i + 14, j + 7, k + 9, Block.stoneSingleSlab.blockID);
		world.setBlock(i + 15, j + 0, k + 0, Block.dirt.blockID);
		world.setBlock(i + 15, j + 0, k + 1, Block.dirt.blockID);
		world.setBlock(i + 15, j + 0, k + 2, Block.dirt.blockID);
		world.setBlock(i + 15, j + 0, k + 3, Block.dirt.blockID);
		world.setBlock(i + 15, j + 0, k + 4, Block.dirt.blockID);
		world.setBlock(i + 15, j + 0, k + 5, Block.dirt.blockID);
		world.setBlock(i + 15, j + 0, k + 6, Block.dirt.blockID);
		world.setBlock(i + 15, j + 0, k + 7, Block.dirt.blockID);
		world.setBlock(i + 15, j + 0, k + 8, Block.dirt.blockID);
		world.setBlock(i + 15, j + 0, k + 9, Block.dirt.blockID);
		world.setBlock(i + 15, j + 0, k + 10, Block.stone.blockID);
		world.setBlock(i + 15, j + 0, k + 11, Block.dirt.blockID);
		world.setBlock(i + 15, j + 0, k + 12, Block.dirt.blockID);
		world.setBlock(i + 15, j + 0, k + 13, Block.dirt.blockID);
		world.setBlock(i + 15, j + 0, k + 14, Block.dirt.blockID);
		world.setBlock(i + 15, j + 0, k + 15, Block.dirt.blockID);
		world.setBlock(i + 15, j + 0, k + 16, Block.dirt.blockID);
		world.setBlock(i + 15, j + 0, k + 17, Block.dirt.blockID);
		world.setBlock(i + 15, j + 0, k + 18, Block.dirt.blockID);
		world.setBlock(i + 15, j + 0, k + 19, Block.dirt.blockID);
		world.setBlock(i + 15, j + 0, k + 20, Block.dirt.blockID);
		world.setBlock(i + 15, j + 1, k + 5, Block.stoneDoubleSlab.blockID);
		world.setBlock(i + 15, j + 1, k + 6, Block.stoneDoubleSlab.blockID);
		world.setBlock(i + 15, j + 1, k + 7, Block.stoneDoubleSlab.blockID);
		world.setBlock(i + 15, j + 1, k + 8, Block.stoneDoubleSlab.blockID);
		world.setBlock(i + 15, j + 1, k + 9, Block.stoneDoubleSlab.blockID);
		world.setBlockMetadataWithNotify(i + 15, j + 1, k + 10, Block.chest.blockID, 2);
		world.setBlock(i + 15, j + 1, k + 11, Block.stoneDoubleSlab.blockID);
		world.setBlock(i + 15, j + 1, k + 14, Block.stoneDoubleSlab.blockID);
		world.setBlock(i + 15, j + 2, k + 5, Block.stone.blockID);
		world.setBlockMetadataWithNotify(i + 15, j + 2, k + 9, Block.stoneSingleSlab.blockID, 8);
		world.setBlock(i + 15, j + 2, k + 11, Block.stone.blockID);
		world.setBlock(i + 15, j + 2, k + 14, Block.stone.blockID);
		world.setBlock(i + 15, j + 3, k + 5, Block.stone.blockID);
		world.setBlock(i + 15, j + 3, k + 11, Block.stone.blockID);
		world.setBlock(i + 15, j + 3, k + 14, Block.stone.blockID);
		world.setBlock(i + 15, j + 4, k + 5, Block.stone.blockID);
		world.setBlock(i + 15, j + 4, k + 11, Block.stone.blockID);
		world.setBlock(i + 15, j + 4, k + 14, Block.stone.blockID);
		world.setBlock(i + 15, j + 5, k + 5, Block.stone.blockID);
		world.setBlock(i + 15, j + 5, k + 11, Block.stone.blockID);
		world.setBlock(i + 15, j + 5, k + 14, Block.stone.blockID);
		world.setBlockMetadataWithNotify(i + 15, j + 5, k + 15, Block.stoneSingleSlab.blockID, 8);
		world.setBlock(i + 15, j + 6, k + 4, Block.stone.blockID);
		world.setBlock(i + 15, j + 6, k + 5, Block.stone.blockID);
		world.setBlock(i + 15, j + 6, k + 7, Block.glowStone.blockID);
		world.setBlock(i + 15, j + 6, k + 9, Block.glowStone.blockID);
		world.setBlock(i + 15, j + 6, k + 10, Block.stoneDoubleSlab.blockID);
		world.setBlock(i + 15, j + 6, k + 11, Block.stoneSingleSlab.blockID);
		world.setBlock(i + 15, j + 6, k + 12, Block.stoneSingleSlab.blockID);
		world.setBlock(i + 15, j + 6, k + 13, Block.stoneSingleSlab.blockID);
		world.setBlock(i + 15, j + 6, k + 14, Block.stoneSingleSlab.blockID);
		world.setBlockMetadataWithNotify(i + 15, j + 7, k + 3, Block.stoneSingleSlab.blockID, 8);
		world.setBlock(i + 15, j + 7, k + 4, Block.stoneSingleSlab.blockID);
		world.setBlock(i + 15, j + 7, k + 5, Block.stoneSingleSlab.blockID);
		world.setBlock(i + 15, j + 7, k + 6, Block.stoneSingleSlab.blockID);
		world.setBlock(i + 15, j + 7, k + 7, Block.stoneSingleSlab.blockID);
		world.setBlock(i + 15, j + 7, k + 8, Block.stoneSingleSlab.blockID);
		world.setBlock(i + 16, j + 0, k + 0, Block.dirt.blockID);
		world.setBlock(i + 16, j + 0, k + 1, Block.dirt.blockID);
		world.setBlock(i + 16, j + 0, k + 2, Block.dirt.blockID);
		world.setBlock(i + 16, j + 0, k + 3, Block.dirt.blockID);
		world.setBlock(i + 16, j + 0, k + 4, Block.dirt.blockID);
		world.setBlock(i + 16, j + 0, k + 5, Block.dirt.blockID);
		world.setBlock(i + 16, j + 0, k + 6, Block.dirt.blockID);
		world.setBlock(i + 16, j + 0, k + 7, Block.dirt.blockID);
		world.setBlock(i + 16, j + 0, k + 8, Block.dirt.blockID);
		world.setBlock(i + 16, j + 0, k + 9, Block.dirt.blockID);
		world.setBlock(i + 16, j + 0, k + 10, Block.dirt.blockID);
		world.setBlock(i + 16, j + 0, k + 11, Block.dirt.blockID);
		world.setBlock(i + 16, j + 0, k + 12, Block.dirt.blockID);
		world.setBlock(i + 16, j + 0, k + 13, Block.dirt.blockID);
		world.setBlock(i + 16, j + 0, k + 14, Block.dirt.blockID);
		world.setBlock(i + 16, j + 0, k + 15, Block.dirt.blockID);
		world.setBlock(i + 16, j + 0, k + 16, Block.dirt.blockID);
		world.setBlock(i + 16, j + 0, k + 17, Block.dirt.blockID);
		world.setBlock(i + 16, j + 0, k + 18, Block.dirt.blockID);
		world.setBlock(i + 16, j + 0, k + 19, Block.dirt.blockID);
		world.setBlock(i + 16, j + 0, k + 20, Block.dirt.blockID);
		world.setBlock(i + 16, j + 1, k + 5, Block.stoneDoubleSlab.blockID);
		world.setBlock(i + 16, j + 1, k + 6, Block.stoneDoubleSlab.blockID);
		world.setBlock(i + 16, j + 1, k + 7, Block.stoneDoubleSlab.blockID);
		world.setBlock(i + 16, j + 1, k + 8, Block.stoneDoubleSlab.blockID);
		world.setBlock(i + 16, j + 1, k + 9, Block.stoneDoubleSlab.blockID);
		world.setBlock(i + 16, j + 1, k + 10, Block.stoneDoubleSlab.blockID);
		world.setBlock(i + 16, j + 1, k + 11, Block.stoneDoubleSlab.blockID);
		world.setBlock(i + 16, j + 1, k + 14, Block.stoneDoubleSlab.blockID);
		world.setBlock(i + 16, j + 2, k + 5, Block.stone.blockID);
		world.setBlockMetadataWithNotify(i + 16, j + 2, k + 9, Block.stoneSingleSlab.blockID, 8);
		world.setBlock(i + 16, j + 2, k + 11, Block.stone.blockID);
		world.setBlock(i + 16, j + 2, k + 14, Block.stone.blockID);
		world.setBlock(i + 16, j + 3, k + 5, Block.stone.blockID);
		world.setBlock(i + 16, j + 3, k + 11, Block.stone.blockID);
		world.setBlock(i + 16, j + 3, k + 14, Block.stone.blockID);
		world.setBlock(i + 16, j + 4, k + 5, Block.stone.blockID);
		world.setBlock(i + 16, j + 4, k + 11, Block.stone.blockID);
		world.setBlock(i + 16, j + 4, k + 14, Block.stone.blockID);
		world.setBlock(i + 16, j + 5, k + 5, Block.stone.blockID);
		world.setBlock(i + 16, j + 5, k + 11, Block.stone.blockID);
		world.setBlock(i + 16, j + 5, k + 14, Block.stone.blockID);
		world.setBlockMetadataWithNotify(i + 16, j + 5, k + 15, Block.stoneSingleSlab.blockID, 8);
		world.setBlock(i + 16, j + 6, k + 4, Block.stone.blockID);
		world.setBlock(i + 16, j + 6, k + 5, Block.stone.blockID);
		world.setBlock(i + 16, j + 6, k + 9, Block.stoneDoubleSlab.blockID);
		world.setBlock(i + 16, j + 6, k + 10, Block.stoneDoubleSlab.blockID);
		world.setBlock(i + 16, j + 6, k + 11, Block.stoneSingleSlab.blockID);
		world.setBlock(i + 16, j + 6, k + 12, Block.stoneSingleSlab.blockID);
		world.setBlock(i + 16, j + 6, k + 13, Block.stoneSingleSlab.blockID);
		world.setBlock(i + 16, j + 6, k + 14, Block.stoneSingleSlab.blockID);
		world.setBlockMetadataWithNotify(i + 16, j + 7, k + 3, Block.stoneSingleSlab.blockID, 8);
		world.setBlock(i + 16, j + 7, k + 4, Block.stoneSingleSlab.blockID);
		world.setBlock(i + 16, j + 7, k + 5, Block.stoneSingleSlab.blockID);
		world.setBlock(i + 16, j + 7, k + 6, Block.stoneSingleSlab.blockID);
		world.setBlock(i + 16, j + 7, k + 7, Block.stoneSingleSlab.blockID);
		world.setBlock(i + 16, j + 7, k + 8, Block.stoneSingleSlab.blockID);
		world.setBlock(i + 17, j + 0, k + 1, Block.dirt.blockID);
		world.setBlock(i + 17, j + 0, k + 2, Block.dirt.blockID);
		world.setBlock(i + 17, j + 0, k + 3, Block.dirt.blockID);
		world.setBlock(i + 17, j + 0, k + 4, Block.dirt.blockID);
		world.setBlock(i + 17, j + 0, k + 5, Block.dirt.blockID);
		world.setBlock(i + 17, j + 0, k + 6, Block.dirt.blockID);
		world.setBlock(i + 17, j + 0, k + 7, Block.dirt.blockID);
		world.setBlock(i + 17, j + 0, k + 8, Block.dirt.blockID);
		world.setBlock(i + 17, j + 0, k + 9, Block.dirt.blockID);
		world.setBlock(i + 17, j + 0, k + 10, Block.dirt.blockID);
		world.setBlock(i + 17, j + 0, k + 11, Block.dirt.blockID);
		world.setBlock(i + 17, j + 0, k + 12, Block.dirt.blockID);
		world.setBlock(i + 17, j + 0, k + 13, Block.dirt.blockID);
		world.setBlock(i + 17, j + 0, k + 14, Block.dirt.blockID);
		world.setBlock(i + 17, j + 0, k + 15, Block.dirt.blockID);
		world.setBlock(i + 17, j + 0, k + 16, Block.dirt.blockID);
		world.setBlock(i + 17, j + 0, k + 17, Block.dirt.blockID);
		world.setBlock(i + 17, j + 0, k + 18, Block.dirt.blockID);
		world.setBlock(i + 17, j + 0, k + 19, Block.dirt.blockID);
		world.setBlock(i + 17, j + 1, k + 5, Block.stoneDoubleSlab.blockID);
		world.setBlock(i + 17, j + 1, k + 6, Block.stoneDoubleSlab.blockID);
		world.setBlock(i + 17, j + 1, k + 7, Block.stoneDoubleSlab.blockID);
		world.setBlock(i + 17, j + 1, k + 8, Block.stoneDoubleSlab.blockID);
		world.setBlock(i + 17, j + 1, k + 9, Block.stoneDoubleSlab.blockID);
		world.setBlock(i + 17, j + 1, k + 10, Block.stoneDoubleSlab.blockID);
		world.setBlock(i + 17, j + 1, k + 11, Block.stoneDoubleSlab.blockID);
		world.setBlock(i + 17, j + 1, k + 12, Block.stoneDoubleSlab.blockID);
		world.setBlock(i + 17, j + 1, k + 13, Block.stoneDoubleSlab.blockID);
		world.setBlock(i + 17, j + 1, k + 14, Block.stoneDoubleSlab.blockID);
		world.setBlock(i + 17, j + 2, k + 5, Block.stone.blockID);
		world.setBlock(i + 17, j + 2, k + 6, Block.stone.blockID);
		world.setBlock(i + 17, j + 2, k + 7, Block.stone.blockID);
		world.setBlock(i + 17, j + 2, k + 8, Block.stone.blockID);
		world.setBlock(i + 17, j + 2, k + 9, Block.stone.blockID);
		world.setBlock(i + 17, j + 2, k + 10, Block.stone.blockID);
		world.setBlock(i + 17, j + 2, k + 11, Block.stone.blockID);
		world.setBlock(i + 17, j + 2, k + 12, Block.stone.blockID);
		world.setBlock(i + 17, j + 2, k + 13, Block.stone.blockID);
		world.setBlock(i + 17, j + 2, k + 14, Block.stone.blockID);
		world.setBlock(i + 17, j + 3, k + 5, Block.stone.blockID);
		world.setBlock(i + 17, j + 3, k + 6, Block.stone.blockID);
		world.setBlock(i + 17, j + 3, k + 7, Block.stone.blockID);
		world.setBlock(i + 17, j + 3, k + 8, Block.stone.blockID);
		world.setBlock(i + 17, j + 3, k + 9, Block.stone.blockID);
		world.setBlock(i + 17, j + 3, k + 10, Block.stone.blockID);
		world.setBlock(i + 17, j + 3, k + 11, Block.stone.blockID);
		world.setBlock(i + 17, j + 3, k + 12, Block.stone.blockID);
		world.setBlock(i + 17, j + 3, k + 13, Block.stone.blockID);
		world.setBlock(i + 17, j + 3, k + 14, Block.stone.blockID);
		world.setBlock(i + 17, j + 4, k + 5, Block.stone.blockID);
		world.setBlock(i + 17, j + 4, k + 6, Block.stone.blockID);
		world.setBlock(i + 17, j + 4, k + 7, Block.stone.blockID);
		world.setBlock(i + 17, j + 4, k + 8, Block.stone.blockID);
		world.setBlock(i + 17, j + 4, k + 9, Block.stone.blockID);
		world.setBlock(i + 17, j + 4, k + 10, Block.stone.blockID);
		world.setBlock(i + 17, j + 4, k + 11, Block.stone.blockID);
		world.setBlock(i + 17, j + 4, k + 12, Block.stone.blockID);
		world.setBlock(i + 17, j + 4, k + 13, Block.stone.blockID);
		world.setBlock(i + 17, j + 4, k + 14, Block.stone.blockID);
		world.setBlock(i + 17, j + 5, k + 5, Block.stone.blockID);
		world.setBlock(i + 17, j + 5, k + 6, Block.stone.blockID);
		world.setBlock(i + 17, j + 5, k + 7, Block.stone.blockID);
		world.setBlock(i + 17, j + 5, k + 8, Block.stone.blockID);
		world.setBlock(i + 17, j + 5, k + 9, Block.stone.blockID);
		world.setBlock(i + 17, j + 5, k + 10, Block.stone.blockID);
		world.setBlock(i + 17, j + 5, k + 11, Block.stone.blockID);
		world.setBlock(i + 17, j + 5, k + 12, Block.stone.blockID);
		world.setBlock(i + 17, j + 5, k + 13, Block.stone.blockID);
		world.setBlock(i + 17, j + 5, k + 14, Block.stone.blockID);
		world.setBlockMetadataWithNotify(i + 17, j + 5, k + 15, Block.stoneSingleSlab.blockID, 8);
		world.setBlock(i + 17, j + 6, k + 4, Block.stone.blockID);
		world.setBlock(i + 17, j + 6, k + 5, Block.stone.blockID);
		world.setBlock(i + 17, j + 6, k + 6, Block.stone.blockID);
		world.setBlock(i + 17, j + 6, k + 7, Block.stone.blockID);
		world.setBlock(i + 17, j + 6, k + 8, Block.stone.blockID);
		world.setBlock(i + 17, j + 6, k + 9, Block.stoneDoubleSlab.blockID);
		world.setBlock(i + 17, j + 6, k + 10, Block.stoneDoubleSlab.blockID);
		world.setBlock(i + 17, j + 6, k + 11, Block.stoneSingleSlab.blockID);
		world.setBlock(i + 17, j + 6, k + 12, Block.stoneSingleSlab.blockID);
		world.setBlock(i + 17, j + 6, k + 13, Block.stoneSingleSlab.blockID);
		world.setBlock(i + 17, j + 6, k + 14, Block.stoneSingleSlab.blockID);
		world.setBlockMetadataWithNotify(i + 17, j + 7, k + 3, Block.stoneSingleSlab.blockID, 8);
		world.setBlock(i + 17, j + 7, k + 4, Block.stoneSingleSlab.blockID);
		world.setBlock(i + 17, j + 7, k + 5, Block.stoneSingleSlab.blockID);
		world.setBlock(i + 17, j + 7, k + 6, Block.stoneSingleSlab.blockID);
		world.setBlock(i + 17, j + 7, k + 7, Block.stoneSingleSlab.blockID);
		world.setBlock(i + 17, j + 7, k + 8, Block.stoneSingleSlab.blockID);
		world.setBlock(i + 18, j + 0, k + 2, Block.dirt.blockID);
		world.setBlock(i + 18, j + 0, k + 3, Block.dirt.blockID);
		world.setBlock(i + 18, j + 0, k + 4, Block.dirt.blockID);
		world.setBlock(i + 18, j + 0, k + 5, Block.dirt.blockID);
		world.setBlock(i + 18, j + 0, k + 6, Block.dirt.blockID);
		world.setBlock(i + 18, j + 0, k + 7, Block.dirt.blockID);
		world.setBlock(i + 18, j + 0, k + 8, Block.dirt.blockID);
		world.setBlock(i + 18, j + 0, k + 9, Block.dirt.blockID);
		world.setBlock(i + 18, j + 0, k + 10, Block.dirt.blockID);
		world.setBlock(i + 18, j + 0, k + 11, Block.dirt.blockID);
		world.setBlock(i + 18, j + 0, k + 12, Block.dirt.blockID);
		world.setBlock(i + 18, j + 0, k + 13, Block.dirt.blockID);
		world.setBlock(i + 18, j + 0, k + 14, Block.dirt.blockID);
		world.setBlock(i + 18, j + 0, k + 15, Block.dirt.blockID);
		world.setBlock(i + 18, j + 0, k + 16, Block.dirt.blockID);
		world.setBlock(i + 18, j + 0, k + 17, Block.dirt.blockID);
		world.setBlock(i + 18, j + 0, k + 18, Block.dirt.blockID);
		world.setBlockMetadataWithNotify(i + 18, j + 5, k + 15, Block.stoneSingleSlab.blockID, 8);
		world.setBlock(i + 18, j + 6, k + 9, Block.stoneDoubleSlab.blockID);
		world.setBlock(i + 18, j + 6, k + 10, Block.stoneDoubleSlab.blockID);
		world.setBlock(i + 18, j + 6, k + 11, Block.stoneSingleSlab.blockID);
		world.setBlock(i + 18, j + 6, k + 12, Block.stoneSingleSlab.blockID);
		world.setBlock(i + 18, j + 6, k + 13, Block.stoneSingleSlab.blockID);
		world.setBlock(i + 18, j + 6, k + 14, Block.stoneSingleSlab.blockID);
		world.setBlockMetadataWithNotify(i + 18, j + 7, k + 3, Block.stoneSingleSlab.blockID, 8);
		world.setBlock(i + 18, j + 7, k + 4, Block.stoneSingleSlab.blockID);
		world.setBlock(i + 18, j + 7, k + 5, Block.stoneSingleSlab.blockID);
		world.setBlock(i + 18, j + 7, k + 6, Block.stoneSingleSlab.blockID);
		world.setBlock(i + 18, j + 7, k + 7, Block.stoneSingleSlab.blockID);
		world.setBlock(i + 18, j + 7, k + 8, Block.stoneSingleSlab.blockID);
		world.setBlock(i + 19, j + 0, k + 3, Block.dirt.blockID);
		world.setBlock(i + 19, j + 0, k + 4, Block.dirt.blockID);
		world.setBlock(i + 19, j + 0, k + 5, Block.dirt.blockID);
		world.setBlock(i + 19, j + 0, k + 6, Block.dirt.blockID);
		world.setBlock(i + 19, j + 0, k + 7, Block.dirt.blockID);
		world.setBlock(i + 19, j + 0, k + 8, Block.dirt.blockID);
		world.setBlock(i + 19, j + 0, k + 9, Block.dirt.blockID);
		world.setBlock(i + 19, j + 0, k + 10, Block.dirt.blockID);
		world.setBlock(i + 19, j + 0, k + 11, Block.dirt.blockID);
		world.setBlock(i + 19, j + 0, k + 12, Block.dirt.blockID);
		world.setBlock(i + 19, j + 0, k + 13, Block.dirt.blockID);
		world.setBlock(i + 19, j + 0, k + 14, Block.dirt.blockID);
		world.setBlock(i + 19, j + 0, k + 15, Block.dirt.blockID);
		world.setBlock(i + 19, j + 0, k + 16, Block.dirt.blockID);
		world.setBlock(i + 19, j + 0, k + 17, Block.dirt.blockID);
		world.setBlock(i + 20, j + 0, k + 4, Block.dirt.blockID);
		world.setBlock(i + 20, j + 0, k + 5, Block.dirt.blockID);
		world.setBlock(i + 20, j + 0, k + 6, Block.dirt.blockID);
		world.setBlock(i + 20, j + 0, k + 7, Block.dirt.blockID);
		world.setBlock(i + 20, j + 0, k + 8, Block.dirt.blockID);
		world.setBlock(i + 20, j + 0, k + 9, Block.dirt.blockID);
		world.setBlock(i + 20, j + 0, k + 10, Block.dirt.blockID);
		world.setBlock(i + 20, j + 0, k + 11, Block.dirt.blockID);
		world.setBlock(i + 20, j + 0, k + 12, Block.dirt.blockID);
		world.setBlock(i + 20, j + 0, k + 13, Block.dirt.blockID);
		world.setBlock(i + 20, j + 0, k + 14, Block.dirt.blockID);
		world.setBlock(i + 20, j + 0, k + 15, Block.dirt.blockID);
		world.setBlock(i + 20, j + 0, k + 16, Block.dirt.blockID);
		world.setBlockMetadataWithNotify(i + 12, j + 3, k + 8, Block.signWall.blockID, 4);
		world.setBlockMetadataWithNotify(i + 12, j + 3, k + 9, Block.signWall.blockID, 4);
		world.setBlock(i + 13, j + 2, k + 6, Block.doorWood.blockID);
		world.setBlockMetadataWithNotify(i + 13, j + 3, k + 6, Block.doorWood.blockID, 8);

		return true;
	}
}